Workbook

Sheet 自动卡用户手册
A1: 这张自动卡是基于赛博朋克红的规则书和群里已有的自动卡设计的，感谢前人的贡献！
A2: 主要是想让卡好看点，视觉上更符合赛博朋克红的感觉，同时更适配面团 | I2: （就我感觉规则书上的卡看着眼睛疼吗？）
A3: 面团建议是可以只打印人物卡，别的边跑边看手机
A5: 根据规则书中的车卡顺序你会依次写RP卡，人物卡，装备卡，状态表
A7: 里面有些自动数值设计不符合规则书，我知道
A8: 例如人性值上限，技能使用的是加点而非等级
A9: 一般情况下不影响游戏，如果你觉得有问题就自己改改
A11: 里面有些数值看着不对劲，这是因为我在里面塞了一点例子，填完自己会好的
A13: 会自动计算属性、技能基准、生命值上限、人性值上限和一些杂七杂八的东西
A15: 你装备的武器和护甲请填写在装备卡中，会自动出现在人物卡
A16: 使用的赛博义体填在状态表里，扣除的人性值会自动减少人性值上限
A17: 如果你通过任何手段降低了义体减少的人性值，直接在状态表的义体统计里修改
A19: 所有使用 | B19: 这个背景颜色 | D19: 的单元格均为自动计算
A20: 随便改会弄坏自动表 | C20: （基本上手动填的就是白色底色）
A22: 有重大问题群里@zcrss，就是我，不保证能改
A24: 推荐使用MiSans Semibold字体以获得最佳体验
A26: 最后，您可以删除此工作表
A27: 祝您游戏愉快！

Sheet 人物卡
B2: 基础信息 | I2: 人物属性 | N2: 调整属性/结果 | S2: 技能
C4: #VALUE! | J4: 智力 | T4: 感官技能 | V4: 调整 | W4: 加点 | X4: 技能基准 | Z4: 教育技能 | AB4: 调整 | AC4: 加点 | AE4: 技能基准 | AG4: 战斗技能 | AI4: 调整 | AJ4: 加点 | AK4: 技能基准
T5: 专注 | X5: =V5+W5+$P$14 -> 0 | Z5: 会计 | AE5: =AC5+AB5+$P$4 -> 0 | AG5: 搏击 | AK5: =AI5+AJ5+$P$8 -> 0
J6: 反应 | T6: 隐藏/发现物品 | X6: =V6+W6+$P$4 -> 0 | Z6: 驯兽 | AE6: =AC6+AB6+$P$4 -> 0 | AG6: 闪避 | AK6: =AI6+AJ6+$P$8 -> 0
T7: 唇语 | X7: =V7+W7+$P$4 -> 0 | Z7: 官场 | AE7: =AC7+AB7+$P$4 -> 0 | AG7: [x2] | AH7: （武术流派） | AK7: =AI7+ROUNDDOWN(AJ7/2,0)+$P$8 -> 0
J8: 敏捷 | T8: 察觉 | X8: =V8+W8+$P$4 -> 0 | Z8: 商务 | AE8: =AC8+AB8+$P$4 -> 0 | AG8: 近战武器 | AK8: =AI8+AJ8+$P$8 -> 0
T9: 追踪 | X9: =V9+W9+$P$4 -> 0 | Z9: 写作 | AE9: =AC9+AB9+$P$4 -> 0 | AG9: 远程武器技能 | AI9: 调整 | AJ9: 加点 | AK9: 技能基准
J10: 技术 | T10: 身体技能 | V10: 调整 | W10: 加点 | X10: 技能基准 | Z10: 犯罪学 | AE10: =AC10+AB10+$P$4 -> 0 | AG10: 弓道 | AK10: =AI10+AJ10+$P$6 -> 0
T11: 运动 | X11: =V11+W11+$P$8 -> 0 | Z11: 密码学 | AE11: =AC11+AB11+$P$4 -> 0 | AG11: [x2]自动武器 | AK11: =AI11+ROUNDDOWN(AJ11/2,0)+$P$6 -> 0
J12: 酷 | T12: 柔韧 | X12: =V12+W12+$P$8 -> 0 | Z12: 推理 | AE12: =AC12+AB12+$P$4 -> 0 | AG12: 手枪 | AK12: =AI12+AJ12+$P$6 -> 0
T13: 舞蹈 | X13: =V13+W13+$P$8 -> 0 | Z13: 通识 | AE13: =AC13+AB13+$P$4 -> 0 | AG13: [x2]重武器 | AK13: =AI13+ROUNDDOWN(AJ13/2,0)+$P$6 -> 0
J14: 意志 | T14: 忍耐 | X14: =V14+W14+$P$14 -> 0 | Z14: 赌博 | AE14: =AC14+AB14+$P$4 -> 0 | AG14: 长管武器 | AK14: =AI14+AJ14+$P$6 -> 0
C15: 头像 | T15: 抗折磨/耐药 | X15: =V15+W15+$P$14 -> 0 | Z15: 图书馆检索 | AE15: =AC15+AB15+$P$4 -> 0 | AG15: 社交技能 | AI15: 调整 | AJ15: 加点 | AK15: 技能基准
C16: 玩家 | J16: 运气 | T16: 潜行 | X16: =V16+W16+$P$8 -> 0 | Z16: 科学 | AE16: =AC16+AB16+$P$4 -> 0 | AG16: 贿赂 | AK16: =AI16+AJ16+$P$12 -> 0
C17: 姓名 | T17: 操作技能 | V17: 调整 | W17: 加点 | X17: 技能基准 | Z17: 战术 | AE17: =AC17+AB17+$P$4 -> 0 | AG17: 交谈 | AK17: =AI17+AJ17+$P$22 -> 0
C18: 外号 | J18: 移速 | T18: 陆地载具 | X18: =V18+W18+$P$6 -> 0 | Z18: 野外生存 | AE18: =AC18+AB18+$P$4 -> 0 | AG18: 察言观色 | AK18: =AI18+AJ18+$P$22 -> 0
C19: 年龄 | E19: 性别 | T19: [x2]空中载具 | X19: =V19+ROUNDDOWN(W19/2,0)+$P$6 -> 0 | Z19: 语言 | AE19: =AC19+AB19+$P$4 -> 0 | AG19: 审讯 | AK19: =AI19+AJ19+$P$12 -> 0
C20: 故乡 | J20: 体格 | T20: 水上载具 | X20: =V20+W20+$P$6 -> 0 | Z20: ┣→ | AA20: 街头俚语 | AE20: =AC20+AB20+$P$4 -> 0 | AG20: 说服 | AK20: =AI20+AJ20+$P$12 -> 0
C21: 等级 | E21: 声望 | T21: 骑术 | X21: =V21+W21+$P$6 -> 0 | Z21: ┣→ | AA21: 母语 | AE21: =AC21+AB21+$P$4 -> 0 | AG21: 个人装扮 | AK21: =AI21+AJ21+$P$12 -> 0
C22: 原生家庭 | J22: 共情 | T22: 表演技能 | V22: 调整 | W22: 加点 | X22: 技能基准 | Z22: ┗→ | AE22: =AC22+AB22+$P$4 -> 0 | AG22: 街头智慧 | AK22: =AI22+AJ22+$P$12 -> 0
O23: =INT(MOD(K32,100)/10)-K22 -> 0 | T23: 表演 | X23: =V23+W23+$P$12 -> 0 | Z23: 本地专家 | AE23: =AC23+AB23+$P$4 -> 0 | AG23: 交易 | AK23: =AI23+AJ23+$P$12 -> 0
J24: 可用点数 | O24: 先攻 调整 | T24: 乐器使用 | X24: =V24+W24+$P$10 -> 0 | Z24: ┣→ | AA24: 你的家 | AE24: =AC24+AB24+$P$4 -> 0 | AG24: 服饰与风格 | AK24: =AI24+AJ24+$P$12 -> 0
B25: 职业 | J25: 剩余点数 | K25: =K24-SUM(K4:K22) -> 0 | T25: ┣→ | X25: =V25+W25+$P$10 -> 0 | Z25: ┣→ | AE25: =AC25+AB25+$P$4 -> 0 | AG25: 技术技能 | AI25: 调整 | AJ25: 加点 | AK25: 技能基准
T26: ┗→ | X26: =V26+W26+$P$10 -> 0 | Z26: ┗→ | AE26: =AC26+AB26+$P$4 -> 0 | AG26: 空中载具技术 | AK26: =AI26+AJ26+$P$10 -> 0
C27: 职业名 | E27: 等级 | AG27: 基础技术 | AK27: =AI27+AJ27+$P$10 -> 0
E28: 能力 | I28: 状态 | AG28: 赛博技术 | AK28: =AI28+AJ28+$P$10 -> 0
C29: 兼职1 | E29: 等级 | J29: 影响血量的意志与体格直接加在人物属性 | S29: 护甲与武器 | AG29: [x2]爆破学 | AK29: =AI29+ROUNDDOWN(AJ29/2,0)+$P$10 -> 0
E30: 能力 | J30: 生命值 | N30: / | O30: =10+ROUNDUP((K20+K14)/2,0)*5 -> 10 | AG30: [x2]电子/安全技术 | AK30: =AI30+ROUNDDOWN(AJ30/2,0)+$P$10 -> 0
C31: 兼职2 | E31: 等级 | T31: 护甲 | W31: 剩余/SP | Y31: 罚值 | AG31: 急救 | AK31: =AI31+AJ31+$P$10 -> 0
E32: 能力 | J32: 人性值 | N32: / | O32: =10*K22-状态表!J5 -> 0 | T32: 头 | U32: =装备卡!D39 -> 0 | X32: =装备卡!J39 -> 0 | Y32: =MAX(装备卡!K39:K41) -> 0 | AA32: 此处罚值不需要再填调整属性，会自动计算 | AG32: [x2]强化急救 | AK32: =AI32+ROUNDDOWN(AJ32/2,0)+$P$10 -> 0
T33: 身 | U33: =装备卡!D40 -> 0 | X33: =装备卡!J40 -> 0 | AG33: 伪造 | AK33: =AI33+AJ33+$P$10 -> 0
C34: 备注 | J34: 人性值变化导致的共情变化会被自动计算 | T34: 盾 | U34: =装备卡!D41 -> 0 | X34: =装备卡!J41 -> 0 | AG34: 地面载具技术 | AK34: =AI34+AJ34+$P$10 -> 0
J35: 严重伤势 | O35: 效果 | T35: 武器 | V35: 伤害 | W35: 剩余/弹药 | Y35: 攻速 | AA35: 备注 | AG35: 绘画/雕刻/摄影 | AK35: =AI35+AJ35+$P$10 -> 0
T36: =装备卡!C5 -> 0 | V36: =装备卡!G5 -> 0 | X36: =装备卡!H5 -> 0 | Y36: =装备卡!I5 -> 0 | AG36: 摄影/摄像 | AK36: =AI36+AJ36+$P$10 -> 0
AG37: 开锁 | AK37: =AI37+AJ37+$P$10 -> 0
T38: =装备卡!C11 -> 0 | V38: =装备卡!G11 -> 0 | X38: =装备卡!H11 -> 0 | Y38: =装备卡!I11 -> 0 | AG38: 扒窃 | AK38: =AI38+AJ38+$P$10 -> 0
AG39: 海洋载具技术 | AK39: =AI39+AJ39+$P$10 -> 0
T40: =装备卡!C17 -> 0 | V40: =装备卡!G17 -> 0 | X40: =装备卡!H17 -> 0 | Y40: =装备卡!I17 -> 0 | AG40: 武器技术 | AK40: =AI40+AJ40+$P$10 -> 0
T42: =装备卡!C23 -> 0 | V42: =装备卡!G23 -> 0 | X42: =装备卡!H23 -> 0 | Y42: =装备卡!I23 -> 0 | AG42: 可用点数 | AJ42: 剩余 | AK42: =AI42-SUM(W5:W9)-SUM(W11:W16)-SUM(W18:W21)-SUM(W23:W26)-SUM(AC5:AC26)-SUM(AJ5:AJ8)-SUM(AJ10:AJ14)-SUM(AJ16:AJ24)-SUM(AJ26:AJ40) -> 0
AG43: 加点列浅红色标记的为必须点的基础加点，技能列红色[x2]的在加点列+2才会+1技能基准
...

Sheet 装备卡
B2: 武器 | E2: 下方已有武器为示例，使用前请删除 | P2: 钱包 | W2: 背包 | Y2: 下方已有物品为示例，使用前请删除
C4: 武器名称 | E4: 武器类型 | F4: 武器技能 | G4: 单次伤害 | H4: 弹药容量 | I4: 攻速 | J4: 需要手数 | K4: 能否隐藏 | L4: 成本 | M4: 价值 | Q4: 专项预算 | R4: 时尚预算 | X4: 物品 | Y4: 描述 | Z4: 数量 | AA4: 成本 | AB4: 价值
R5: 义体赞助
C6: 备注 | Q6: 流动资金 | R6: 初始资金
C7: 配件 | R7: 收益
R8: 购物支出 | S8: =SUM(L5,L7:L9,L11,L13:L15,L17,L19:L21,L23,L25:L27,L29,L31:L33,L39:L41)+状态表!H5+SUM(AA5:AA41) -> 0
R9: 消耗支出
C10: 武器名称 | E10: 武器类型 | F10: 武器技能 | G10: 单次伤害 | H10: 弹药容量 | I10: 攻速 | J10: 需要手数 | K10: 能否隐藏 | L10: 成本 | M10: 价值 | R10: 总计 | S10: =SUM(S6:T7)-SUM(S8:T9) -> 0
Q11: 会自动计算表格里填的，已消耗的消耗品和购买服务等花费填在消耗支出里
C12: 备注
C13: 配件
P14: 衣食住行 | S14: 这里不会参与自动计算
C16: 武器名称 | E16: 武器类型 | F16: 武器技能 | G16: 单次伤害 | H16: 弹药容量 | I16: 攻速 | J16: 需要手数 | K16: 能否隐藏 | L16: 成本 | M16: 价值 | Q16: 生活风格 | S16: 花费
C18: 备注 | Q18: 住所 | S18: 花费
C19: 配件
Q20: 本月已支付 | S20: 总开销
S21: =S19+S17 -> 0
C22: 武器名称 | E22: 武器类型 | F22: 武器技能 | G22: 单次伤害 | H22: 弹药容量 | I22: 攻速 | J22: 需要手数 | K22: 能否隐藏 | L22: 成本 | M22: 价值 | Q22: 时尚衣物 | S22: 数量 | T22: 单价
C24: 备注
C25: 配件
C28: 武器名称 | E28: 武器类型 | F28: 武器技能 | G28: 单次伤害 | H28: 弹药容量 | I28: 攻速 | J28: 需要手数 | K28: 能否隐藏 | L28: 成本 | M28: 价值
C30: 备注
C31: 配件
R33: 时尚总费用 | T33: =S23*T23+S24*T24+S25*T25+S26*T26+S27*T27+S28*T28+S29*T29+S30*T30+S31*T31+S32*T32 -> 0
B36: 护甲 | E36: 下方已有护甲为示例，使用前请删除
C38: 护甲部位 | D38: 护甲名称 | E38: 护甲类型 | G38: 备注 | J38: 阻滞力 | K38: 护甲惩罚 | L38: 成本 | M38: 价值
C39: 头部
C40: 身体
C41: 盾牌

Sheet 状态表
B2: 义体统计 | E2: 下方已有义体为示例，使用前请删除 | M2: 伤势 | P2: 仅供参考，不参与自动计算 | AA2: 精神状态 | AD2: 仅供参考，不参与自动计算
H4: 总成本 | I4: 总价值 | J4: 总人性损失 | N4: 生命值 | O4: 总生命值 | P4: 伤势状态 | Q4: 伤势效果 | T4: 救治难度 | U4: 左侧伤势状态自动计算， 生命值变化时请调整人物卡 | AB4: 人性值 | AC4: 人性值上限 | AD4: 共情 | AE4: 精神状态
H5: =SUM(H7:H53) -> 0 | I5: =SUM(I7:I51) -> 0 | J5: =SUM(J7:J55) -> 0 | N5: =人物卡!K30 -> 0 | O5: =人物卡!O30 -> 10 | P5: =IF(N5=0,"致命伤",IF(N5<O5,IF(N5<O5/2,"重伤","轻伤"),"健康")) -> 健康 | Q5: =IF($P$5="健康","无",IF($P$5="轻伤","无",IF($P$5="重伤","所有动作检定-2",IF($P$5="致命伤","所有动作的检定 -4，移速属性 -6（最低剩余 1）",2)))) -> 无 | T5: {=IF($P$5="健康","无",IF($P$5="轻伤","10",IF($P$5="重伤","13",IF($P$5="致命伤","15",_xleta.XIRR))))} -> 无 | AB5: =人物卡!K32 -> 0 | AC5: =人物卡!O32 -> 0 | AD5: =人物卡!P22 -> 0 | AE5: =IF(AD5<0,"严重赛博精神病",IF(AD5=0,"赛博精神病",IF(AD5=1,"分离性精神障碍",IF(AD5=2,"边缘分离性精神障碍","健康")))) -> 健康
C6: 基础义体 | D6: 插槽 | E6: 组件名 | F6: 安装设施 | G6: 描述和数据 | H6: 成本 | I6: 价值 | J6: 人性损失 | AB6: 人性值变动记录
N7: 身体严重伤势 | AB7: 项目 | AD7: 人性值变化
N8: 是否受伤 | O8: 2D6 | P8: 严重伤势 | Q8: 伤势效果 | V8: 紧急处理 | W8: 治愈 | AB8: 义体 | AD8: =-J5 -> 0
N9: 否 | O9: 2 | P9: 断臂 | Q9: 断掉的那只手臂，没了。那只手里拿着的任何东西都掉了。基础死亡豁免惩罚减值 +1。 | V9: 做不到 | W9: 手术DV17
N11: 否 | O11: 3 | P11: 断手 | Q11: 断掉的那只手，没了。那只手里拿着的任何东西都掉了。基础死亡豁免惩罚减值 +1。 | V11: 做不到 | W11: 手术DV17
N13: 否 | O13: 4 | P13: 气胸 | Q13: 移速属性 -2（最低 1）， 基础死亡豁免惩罚减值 +1。 | V13: 强化急救DV15 | W13: 手术DV15
N15: 否 | O15: 5 | P15: 肋骨骨折 | Q15: 在每个你徒步行进了超过 4m 的回合后，你都要重新受到这个严重伤势的额外伤害，直接从生命值里扣除。 | V15: 强化急救DV13 | W15: 强化急救DV15/ 手术DV13
N17: 否 | O17: 6 | P17: 手臂骨折 | Q17: 骨折的手臂无法再用来干别的事了，那只手里拿着的任何东西，都掉了。 | V17: 强化急救DV13 | W17: 强化急救DV15/ 手术DV13
N19: 否 | O19: 7 | P19: 体内异物 | Q19: 在每个你徒步行进了超过 4m 的回合后，你都要重新受到这个严重伤势的额外伤害，直接从生命值里扣除。 | V19: 急救/强化急救DV13 | W19: 紧急处理可治愈 | AA19: 药物状态
N21: 否 | O21: 8 | P21: 小腿/大腿骨折 | Q21: 移速属性 -4（最低 1） | V21: 强化急救DV13 | W21: 强化急救DV15/ 手术DV13 | AB21: 是否成瘾 | AC21: 药物名称 | AD21: 备注
N23: 否 | O23: 9 | P23: 肌肉撕裂 | Q23: 近战攻击判定 -2 | V23: 急救/强化急救DV13 | W23: 紧急处理可治愈
N25: 否 | O25: 10 | P25: 脊柱受伤 | Q25: 在你的下个回合里你无法使用其他动作，但仍然可以进行移动动作。基础死亡豁免惩罚减值 +1。 | V25: 强化急救DV15 | W25: 手术DV15
N27: 否 | O27: 11 | P27: 手指粉碎性骨折 | Q27: 用到那只手的任何动作判定 -4 | V27: 强化急救DV13 | W27: 手术DV15
N29: 否 | O29: 12 | P29: 断腿 | Q29: 断掉的那条腿，没了。移速 -6（最低 1）。你无法闪避攻击。基础死亡豁免惩罚减值 +1。 | V29: 做不到 | W29: 手术DV17
N31: 头部严重伤势
N32: 是否受伤 | O32: 2D6 | P32: 严重伤势 | Q32: 伤势效果 | V32: 紧急处理 | W32: 治愈
N33: 否 | O33: 2 | P33: 失去眼睛 | Q33: 你的一只眼睛不见了。远程攻击和所有需要视觉的觉察判定 -4。基础死亡豁免惩罚减值 +1。 | V33: 做不到 | W33: 手术DV17
N35: 否 | O35: 3 | P35: 脑损伤 | Q35: 所有动作判定 -2，基础死亡豁免惩罚减值 +1。 | V35: 做不到 | W35: 手术DV17
N37: 否 | O37: 4 | P37: 眼睛受损 | Q37: 远程攻击和所有需要视觉的觉察判定 -2。 | V37: 强化急救DV15 | W37: 手术DV13
N39: 否 | O39: 5 | P39: 脑震荡 | Q39: 所有动作判定 -2。 | V39: 急救/强化急救DV13 | W39: 紧急处理可治愈
N41: 否 | O41: 6 | P41: 领骨骨折 | Q41: 需要说话的所有动作判定 -4。 | V41: 强化急救DV15 | W41: 强化急救DV15/ 手术DV13
N43: 否 | O43: 7 | P43: 头部异物 | Q43: 在每个你徒步行进了超过 4m 的回合后，你都要重新 受到这个严重伤势的额外伤害，直接从生命值里扣除。 | V43: 急救/强化急救DV13 | W43: 紧急处理可治愈
N45: 否 | O45: 8 | P45: 挥鞭伤 | Q45: 基础死亡豁免惩罚减值 +1。 | V45: 强化急救DV13 | W45: 强化急救/ 手术DV13
N47: 否 | O47: 9 | P47: 颅骨骨裂 | Q47: 瞄准你头部的瞄准射击造成的伤害在减去阻滞力之后倍数变为 3( 而不是 2)，基础死亡豁免惩罚减值 +1。 | V47: 强化急救DV15 | W47: 强化急救/ 手术DV15
N49: 否 | O49: 10 | P49: 耳朵受损 | Q49: 在每个你徒步行进了超过 4m 的回合后，下个回合将无法做出移动动作。所有需要听力的觉察判定 -2。 | V49: 强化急救DV13 | W49: 手术DV13
N51: 否 | O51: 11 | P51: 气管破裂 | Q51: 你说话只有含混的嘶嘶气声，无法说话。基础死亡豁免惩罚减值 +1。 | V51: 做不到 | W51: 手术DV15
N53: 否 | O53: 12 | P53: 失去耳朵 | Q53: 你的一只耳朵不见了。在每个你徒步行进了超过 4m的回合后，下个回合将无法做出移动动作。所有需要听力的觉察判定 -4，基础死亡豁免惩罚减值 +1。 | V53: 做不到 | W53: 手术DV17

Sheet RP卡
B2: 生命路径 | G2: 朋友 | S2: 精神病症状
C4: 风格 | H4: 名字 | I4: 你们的关系 | L4: 详细描述
C5: 文化区域
C6: 母语
C7: 性格
C8: 发型
C9: 衣着风格
C10: 动机
C11: 个性
C12: 最看重
C13: 最在乎
C14: 观点
C15: 宝物 | G15: 爱情
C16: 目标
C17: 家庭背景 | H17: 名字 | I17: 发生了什么 | L17: 详细描述
C18: 原生家庭
C19: 同年环境
C20: 家庭危机
C26: 基于职业的生命路径
G28: 人物背景故事
B40: 敌人
C42: 名字 | D42: 关系如何 | E42: 什么导致的 | J42: 他会怎么样来找你 | M42: 你打算怎么做 | P42: 详细描述

Sheet 成长表
B2: I.P.统计 | E2: 此工作表不参与自动计算，为记录用。 | I2: 成长记录 | L2: 此工作表不参与自动计算，为记录用。
C4: I.P.点 | J4: 时间 | K4: 模组 | L4: 获得声望 | M4: 获得资金 | N4: 获得物品 | O4: 人性事件 | P4: 人性增减 | Q4: 资金来源 | R4: 物品来源 | S4: 重要的时刻
C5: 已获得 | D5: 属性消耗 | E5: 技能消耗 | F5: 剩余
D6: =SUM(F9:F18) -> 0 | E6: =SUM(F21:F50) -> 0 | F6: =C6-D6-E6 -> 0
C7: 能力成长表
C8: 职业能力 | D8: 初始等级 | E8: 成长等级 | F8: 已消耗I.P.
C9: 魅力冲击
C10: 战斗直觉
C11: 交互界面
C12: 能工巧匠
C13: 医疗圣手
C14: 公众信誉
C15: 团队合作
C16: 后备支援
C17: 八面玲珑
C18: 引擎之友
C19: 技能成长表
C20: 技能名称 | D20: 原始技能 | E20: 成长技能 | F20: 已消耗I.P.
